Workbook
Name SegmentaçãodeDados_ESTRATO_DE_PRODUÇÃO__L_DIA: #N/A
Name SegmentaçãodeDados_Município: #N/A
Name SegmentaçãodeDados_TIPOLOGIA_DA_PRODUÇÃO_DE_LEITE: #N/A

Sheet DADOS 1
A1: Nome | B1: Município | C1: TIPOLOGIA DA PRODUÇÃO DE LEITE | D1: ESTRATO DE PRODUÇÃO (L/DIA) | E1: 1.2. Topografia/relevo predominante da propriedade rural: | F1: 1.5. Sistema de produção de leite cru? | G1: 1.6. Tipos de benfeitorias na propriedade rural (Marque o tipo de construção para cada benfeitoria) [Casa sede] | H1: 1.6. Tipos de benfeitorias na propriedade rural (Marque o tipo de construção para cada benfeitoria) [Casa/alojamento de empregado] | I1: 1.6. Tipos de benfeitorias na propriedade rural (Marque o tipo de construção para cada benfeitoria) [Galpão para máquinas, implementos e afins] | J1: 1.7. Existência de recursos hídricos e serviços na propriedade rural: | K1: CAR - Cadastro Ambiental Rural | L1: Cursos d’água/riacho/nascentes/mina | M1: Vegetação nativa/mata/floresta | N1: Área de preservação permanentes | O1: Área de reserva legal | P1: Serviço de água potável | Q1: Serviço de esgoto doméstico tratado | R1: Serviço de telefonia | S1: 2.1. Idade (anos) | T1: 2.2. Tempo que é produtor(a) de leite (anos) | U1: 2.3. Sexo | V1: 2.4. Escolaridade: | W1: 2.5. Residência principal (mais de 50% do tempo): | X1: 2.6. Distribuição da área utilizada na produção leiteira: Própria (%) | Y1: 2.6. Distribuição da área utilizada na produção leiteira: Arrendada (%) | Z1: 2.6. Distribuição da área utilizada na produção leiteira: Parceria (%) | AA1: 2.6. Distribuição da área utilizada na produção leiteira: Comodato (%) | AB1: 2.6. Distribuição da área utilizada na produção leiteira: Assentamento (%) | AC1: 2.6. Distribuição da área utilizada na produção leiteira: Como posseiro (%) | AD1: 2.7. Origem da área própria utilizada na atividade leiteira: Herança ou doação (%) | AE1: 2.7. Origem da área própria utilizada na atividade leiteira: Compra (%) | AF1: 2.7. Origem da área própria utilizada na atividade leiteira: Posse ou usucapião (%) | AG1: 2.7. Origem da área própria utilizada na atividade leiteira: Titulação ou licença de ocupação (%) | AH1: 2.7. Origem da área própria utilizada na atividade leiteira: Outro (%) | AI1: 2.8. Faz parte de alguma associação ou cooperativa relacionada à produção de leite? | AJ1: 2.9. Composição da renda bruta do produtor rural: Pecuária de leite (%) | AK1: 2.9. Composição da renda bruta do produtor rural: Outras criações (%) | AL1: 2.9. Composição da renda bruta do produtor rural: Culturas permanentes (%) | AM1: 2.9. Composição da renda bruta do produtor rural: Culturas anuais (%) | AN1: 2.9. Composição da renda bruta do produtor rural: Fora da propriedade (%) | AO1: 2.10. Composição da renda bruta da atividade leiteira: Venda e consumo de leite (%) | AP1: 2.10. Composição da renda bruta da atividade leiteira: Venda e consumo de animais (%) | AQ1: 2.10. Composição da renda bruta da atividade leiteira: Outro (%) | AR1: 2.11. Recebe ou acessa algum benefício social no âmbito do governo? (Pode marcar mais de uma opção) | AS1: Bolsa família | AT1: Aposentadoria | AU1: PRONAF | AV1: PRONAMPE | AW1: Seguro Safra | AX1: Programa de Aquisição de Alimentos (PAA) | AY1: Programa de Garantia de Preços para a Agricultura Familiar (PGPAF) | AZ1: Benefício de Prestação Continuada | BA1: Outro programa municipal/estadual | BB1: Não recebe benefício do governo | BC1: 3.1. Atualmente, seu retorno financeiro na produção de leite pode ser considerado: | BD1: 3.2. Sua atividade leiteira se mantém sem recursos externos? | BE1: 3.3. Por que está na atividade do leite? (Marque no máximo 3 alternativas) | BF1: Por gostar | BG1: Por ser uma atividade lucrativa | BH1: Por proporcionar renda mensal | BI1: A atividade leiteira é uma tradição na família | BJ1: Combina com outras explorações da propriedade | BK1: Tem mercado garantido | BL1: Não sabe fazer outra coisa | BM1: Emprega a família | BN1: Não sabe | BO1: 3.4. Excluindo o preço do leite, quais os principais problemas que influenciam na sua produção? (Marque no máximo 3 alternativas) | BP1: Falta de mão de obra | BQ1: Deficiência na qualificação da mão de obra | BR1: Falta de crédito rural, com taxas de juros compatíveis com a atividade | BS1: Deficiência de informações técnicas sobre a produção de leite | BT1: Deficiência de informações de mercado | BU1: Custo dos insumos | BV1: Deficiência na infraestrutura de transporte/estradas | BW1: Instabilidade de políticas públicas | BX1: Legislação ambiental | BY1: Legislação trabalhista | BZ1: Baixa capacidade de endividamento | CA1: Não sabe | CB1: 3.6. Na sua opinião, quais os pontos mais importantes para uma produção de leite rentável? (Marque no máximo 3 alternativas) | CC1: Mão de obra qualificada | CD1: Sanidade do rebanho | CE1: Qualidade genética dos animais | CF1: Alimentação do rebanho | CG1: Manejo do rebanho | CH1: Reprodução do rebanho | CI1: Preço do leite | CJ1: Conhecimento de técnicas eficientes | CK1: Não sabe | CL1: 3.7. Para os próximos 5 anos, o que pretende fazer com a produção de leite? | CM1: 3.8. Opinião do produtor sobre a sucessão em sua propriedade: | CN1: 4.1. Utilizou crédito rural nos últimos 12 meses? | CO1: 4.2. Se utilizou, quais as principais linhas de crédito? (Pode marcar mais de uma opção) | CP1: PRONAF | CQ1: INOVAGRO | CR1: PRONAMPE | CS1: Cooperativas de crédito ou bancos privados | CT1: Plano Safra | CU1: Crédito Informal | CV1: Não utilizou crédito | CW1: 4.3. Se não utilizou crédito, por quê? (Pode marcar mais de uma opção) | CX1: Documentação pessoal incompleta | CY1: Falta de regularização fundiária | CZ1: Não tem capacidade para endividamento | DA1: Dificuldade para obter financiamento | DB1: Não precisou de crédito | DC1: Utilizou crédito | DD1: 5.2. Produção de leite média dos últimos 12 meses (consumido + vendido) (litros/dia) | DE1: 5.2.1. Produção nas águas (litros/dia) | DF1: 5.2.2. Produção na seca (litros/dia) | DG1: 5.3. Produtividade média / vaca em lactação (litros/vaca/dia) | DH1: 5.3.1. Produtividade nas águas (litros/vaca/dia) | DI1: 5.3.2 Produtividade na seca (litros/vaca/dia) | DJ1: 5.4. Distribuição da produção de leite nos últimos 12 meses: Vendida para laticínio/cooperativa (leite fluído) (%) | DK1: 5.4. Distribuição da produção de leite nos últimos 12 meses: Vendida diretamente para consumidor (leite fluído) (%) | DL1: 5.4. Distribuição da produção de leite nos últimos 12 meses: Vendida na forma de derivados (queijos, requeijão, etc.) (%) | DM1: 5.4. Distribuição da produção de leite nos últimos 12 meses: Autoconsumo humano (%) | DN1: 5.4. Distribuição da produção de leite nos últimos 12 meses: Aleitamento (%) | DO1: 5.5. Área própria total da propriedade (hectares) | DP1: 5.6. Área destinada ao gado de leite (hectares) | DQ1: 5.7.1. Possui cônjuge ou companheiro(a)? | DR1: Tem filhos | DS1: Tem filhos que trabalham na propriedade rural | DT1: TOTAL FAMILIAR (TRABALHADOR/DIA) | DU1: TOTAL CONTRATADA (TRABALHADOR/DIA) | DV1: MDO TOTAL (TRABALHADOR/DIA) | DW1: 5.11.1. Número atual de cabeças no rebanho: Vaca em lactação | DX1: 5.11.1. Número atual de cabeças no rebanho: Vaca seca | DY1: 5.11.1. Número atual de cabeças no rebanho: Bezerra em aleitamento | DZ1: 5.11.1. Número atual de cabeças no rebanho: Bezerro em aleitamento | EA1: 5.11.1. Número atual de cabeças no rebanho: Novilha em recria | EB1: 5.11.1. Número atual de cabeças no rebanho: Novilha em reprodução | EC1: 5.11.1. Número atual de cabeças no rebanho: Garrote | ED1: 5.11.1. Número atual de cabeças no rebanho: Touro | EE1: 5.11.1. Número atual de cabeças no rebanho: Animal de serviço | EF1: 5.11.2.a. Composição % do rebanho - Reprodutores (touro/sêmen): Menos de 1/2 HZ (azebuado) (%) | EG1: 5.11.2.a. Composição % do rebanho - Reprodutores (touro/sêmen): De 1/2 a 3/4 HZ (%) | EH1: 5.11.2.a. Composição % do rebanho - Reprodutores (touro/sêmen): De 3/4 a 7/8 HZ (%) | EI1: 5.11.2.a. Composição % do rebanho - Reprodutores (touro/sêmen): De 7/8 HZ a puro holandês (%) | EJ1: 5.11.2.a. Composição % do rebanho - Reprodutores (touro/sêmen): Puro holandês (%) | EK1: 5.11.2.a. Composição % do rebanho - Reprodutores (touro/sêmen): Puro outras raças europeias (%) | EL1: 5.11.2.a. Composição % do rebanho - Reprodutores (touro/sêmen): Puro raças zebuínas (%) | EM1: 5.11.2.a. Composição % do rebanho - Reprodutores (touro/sêmen): Sem padrão definido (%) | EN1: 5.11.2.b. Composição % do rebanho - Vacas (lactação + secas): Menos de 1/2 HZ (azebuado) (%) | EO1: 5.11.2.b. Composição % do rebanho - Vacas (lactação + secas): De 1/2 a 3/4 HZ (%) | EP1: 5.11.2.b. Composição % do rebanho - Vacas (lactação + secas): De 3/4 a 7/8 HZ (%) | EQ1: 5.11.2.b. Composição % do rebanho - Vacas (lactação + secas): De 7/8 HZ a puro holandês (%) | ER1: 5.11.2.b. Composição % do rebanho - Vacas (lactação + secas): Puro holandês (%) | ES1: 5.11.2.b. Composição % do rebanho - Vacas (lactação + secas): Puro outras raças europeias (%) | ET1: 5.11.2.b. Composição % do rebanho - Vacas (lactação + secas): Puro raças zebuínas (%) | EU1: 5.11.2.b. Composição % do rebanho - Vacas (lactação + secas): Sem padrão definido (%) | EV1: 6.1. Como é feito o resfriamento do leite na fazenda? | EW1: 6.4. Tem fonte de água no curral? | EX1: 6.5. Tem cobertura no curral? | EY1: 6.6. Estrutura do local de ordenha: | EZ1: 6.7. Tem fonte de água no local de ordenha? | FA1: 6.8. A Sala de ordenha é coberta? | FB1: 6.9. Tipo de ordenha: | FC1: 6.10. Número de ordenhas nas águas | FD1: 6.10. Número de ordenhas na seca | FE1: 6.12. O leite é enviado ao laticínio: | FF1: 6.15. Tipo de pastagem na propriedade rural: | FG1: 6.16. Tipo de pastagem plantada na propriedade rural: (Pode marcar mais de uma opção) | FH1: Brachiaria | FI1: Panicum | FJ1: Capim-elefante | FK1: Colonião | FL1: Jaraguá | FM1: Andropogon | FN1: Cynodon | FO1: Tifton | FP1: Não tem pastagem plantada | FQ1: 6.17. Quais dessas práticas são utilizadas nas pastagens? (Pode marcar mais de uma opção) | FR1: Correção e adubação do solo na implantação | FS1: Adubação anual de cobertura | FT1: Controle de plantas invasoras | FU1: Rotação de pastagens | FV1: Divisão em piquetes | FW1: Cerca elétrica nos piquetes | FX1: Nenhuma das anteriores | FY1: Não utiliza pastagens | FZ1: 7.1. Quem faz a administração/direção da atividade leiteira? | GA1: 7.2. Quais metas anuais são estabelecidas para a atividade leiteira? (Pode marcar mais de uma opção) | GB1: Produção de leite | GC1: Produtividade | GD1: Receitas | GE1: Despesas | GF1: Venda de genética | GG1: Venda de animais | GH1: Não estabelece metas | GI1: 7.4. Realização de controle financeiro da produção: | GJ1: 7.5. Sabe qual o custo médio da sua produção de leite? | GK1: 7.6. Se sim, qual o valor médio anual do seu custo de produção? (R$/litro) | GL1: 8.1. Quais as principais fontes de informações sobre gado de leite? (Marque no máximo 3 alternativas) | GM1: Assistência técnica | GN1: Vizinho, amigo ou parente | GO1: Treinamento (curso, palestra, etc.) | GP1: Jornais e revistas agropecuários | GQ1: Programas de TV | GR1: Outras mídias sociais | GS1: 8.4. Nos últimos 12 meses, quantas vezes um técnico visitou sua propriedade para orientá-lo(a) sobre a produção de leite? (visitas/ano) | GT1: 8.6. Quais informações sobre a produção de leite mais recebeu? (Marque no máximo 3 alternativas) | GU1: Planejamento da empresa rural | GV1: Cálculo do custo de produção | GW1: Mercado do leite | GX1: Alimentação do rebanho | GY1: Sanidade do rebanho | GZ1: Manejo do rebanho | HA1: Melhoramento genético | HB1: Gerenciamento da produção | HC1: Produção de leite e meio ambiente | HD1: Qualidade do leite | HE1: Não sabe | HF1: 8.7. Quais informações sobre a produção de leite tem mais carência? (Marque no máximo 3 alternativas) | HG1: Planejamento da empresa rural | HH1: Cálculo do custo de produção | HI1: Mercado do leite | HJ1: Alimentação do rebanho | HK1: Sanidade do rebanho | HL1: Manejo do rebanho | HM1: Melhoramento genético | HN1: Gerenciamento da produção | HO1: Produção de leite e meio ambiente | HP1: Qualidade do leite | HQ1: Não sabe | HR1: 9.1. Distribuição % aproximada das vacas em lactação em cada tipo de sistema: Freestall (%) | HS1: 9.1. Distribuição % aproximada das vacas em lactação em cada tipo de sistema: Compost Barn (%) | HT1: 9.1. Distribuição % aproximada das vacas em lactação em cada tipo de sistema: Semiconfinado (%) | HU1: 9.1. Distribuição % aproximada das vacas em lactação em cada tipo de sistema: Piquete rotacionado (%) | HV1: 9.1. Distribuição % aproximada das vacas em lactação em cada tipo de sistema: Pasto extensivo (%) | HW1: 9.2. Utiliza técnicas para conforto dos animais? (Pode marcar mais de uma opção) | HX1: Galpão coberto | HY1: Sombrite ou tela de sombreamento | HZ1: Cobertura vegetal (árvores, sombra natural) | IA1: Exaustores | IB1: Ventiladores mecânicos | IC1: Aspersores ou nebulizadores | ID1: Sistema de resfriamento evaporativo | IE1: Bebedouros | IF1: Controle automatizado de temperatura/umidade | IG1: Piso emborrachado ou drenante nas áreas de espera | IH1: 9.3. Possui energia elétrica na propriedade? | II1: 9.4. Possui internet na propriedade? | IJ1: 9.7. Quais desses equipamentos próprios são utilizados na produção de leite: (Pode marcar mais de uma opção) | IK1: Picadeira | IL1: Balança para os animais | IM1: Trator | IN1: Vagão forrageiro | IO1: Plantadeira | IP1: Grade | IQ1: Arado | IR1: Ensiladeira | IS1: Distribuidor de calcário | IT1: Misturador de ração | IU1: 9.8. Qual o destino de dejetos líquidos e sólidos? (Pode marcar mais de uma opção) | IV1: 9.9. Quais dessas técnicas sustentáveis são utilizadas? (Pode marcar mais de uma opção) | IW1: Plantio direto | IX1: Cobertura do solo | IY1: Descarte adequado de embalagens (herbicida e defensivos) | IZ1: Tratamento de efluentes da residência | JA1: Rotação de culturas | JB1: 10.1. Idade média que desfaz dos machos (meses) | JC1: 10.2. Idade média de desmama dos bezerros(as) (meses) | JD1: 10.3. Peso médio ao desmame dos bezerros(as) (Kg) | JE1: 10.4. Idade média das novilhas ao primeiro parto (meses) | JF1: 10.5. Intervalo entre partos médio (meses) | JG1: 10.6. Taxa de mortalidade média de bezerros (%) | JH1: 10.7. Taxa de mortalidade média de animais adultos (%) | JI1: 10.9. Quais critérios sanitários contra enfermidades são aplicados ao rebanho: (Pode marcar mais de uma opção) | JJ1: Manqueira | JK1: Brucelose | JL1: Paratifo | JM1: Raiva | JN1: Enterotoxemia | JO1: Botulismo | JP1: Vermifugação | JQ1: Carrapaticida | JR1: IBR/BVD | JS1: Leptospirose | JT1: 10.10. Técnicas utilizadas no manejo de ordenha: (Pode marcar mais de uma opção) | JU1: Teste da caneca | JV1: Pré-dipping | JW1: Pós-dipping | JX1: Linha de ordenha | JY1: Alimentação durante a ordenha | JZ1: Alimentação após a ordenha | KA1: Identificação de animais tratados com antibiótico | KB1: 10.11. Sistema de reprodução: (Pode marcar mais de uma opção) | KC1: FIV/TE | KD1: Inseminação artificial/IATF | KE1: Natural controlada | KF1: Natural não controlada | KG1: 10.12. Tipo de aleitamento: | KH1: 10.13. Critério para primeira cobertura: | KI1: 10.14. Frequência de uso do concentrado para vacas em lactação: | KJ1: 10.15. Quando usa concentrado ele é distribuído de acordo com a produção das vacas? | KK1: 10.16. Tipo de suplementação volumosa utilizado: (Pode marcar mais de uma opção) | KL1: Cana-de-açúcar | KM1: Capineira | KN1: Silagem de capim | KO1: Silagem de milho | KP1: Silagem de sorgo | KQ1: Outra silagem | KR1: Feno | KS1: Palma | KT1: Não fornece suplementação | KU1: 11.2. Há quanto tempo vende para o mesmo comprador? (anos) | KV1: 11.3. Preço recebido no último mês? (R$/litro) | KW1: 11.4. Preço médio recebido nas águas? (R$/litro) | KX1: 11.5. Preço médio recebido na seca? (R$/litro) | KY1: 11.7. Quais bonificações são realizadas pelo laticínio que compra seu leite: (Pode marcar mais de uma opção) | KZ1: Volume de leite entregue | LA1: Nível de CCS | LB1: Nível de CBT | LC1: Teor de gordura | LD1: Teor de proteína | LE1: Critérios de sustentabilidade e BPA | LF1: Não sabe | LG1: 11.8. Qual sua opinião sobre o sistema de pagamento com bonificação? [Por volume de leite] | LH1: 11.8. Qual sua opinião sobre o sistema de pagamento com bonificação? [Por qualidade do leite] | LI1: 11.8. Qual sua opinião sobre o sistema de pagamento com bonificação? [Por critérios de sustentabilidade] | LJ1: 11.9. Tem contrato formal com o laticínio que compra seu leite? | LK1: 11.10. Como avalia a importância de um contrato formal com o laticínio?
B2: Coimbra | C2: Não familiar | D2: 4) 1001 a 2500 | E2: Suavemente acidentado ou acidentado | F2: Intensivo | G2: Alvenaria | H2: Alvenaria | I2: Alvenaria | J2: CAR - Cadastro Ambiental Rural, Cursos d’água/riacho/nascentes/mina, Área de preservação permanentes, Área de reserva legal, Serviço de telefonia | K2: Sim | L2: Sim | N2: Sim | O2: Sim | R2: Sim | S2: 65 | T2: 34 | U2: Masculino | V2: Pós-graduação | W2: Na cidade | X2: 100 | Y2: 0 | Z2: 0 | AA2: 0 | AB2: 0 | AC2: 0 | AD2: 0 | AE2: 100 | AF2: 0 | AG2: 0 | AH2: 0 | AI2: Não | AJ2: 10 | AK2: 0 | AL2: 0 | AM2: 70 | AN2: 20 | AO2: 95 | AP2: 5 | AQ2: 0 | AR2: Aposentadoria | AT2: Sim | BC2: Regular | BD2: Não | BE2: Por gostar | BF2: Sim | BO2: Falta de crédito rural, com taxas de juros compatíveis com a atividade, Instabilidade de políticas públicas, Legislação trabalhista | BR2: Sim | BW2: Sim | BY2: Sim | CB2: Qualidade genética dos animais, Alimentação do rebanho, Reprodução do rebanho | CE2: Sim | CF2: Sim | CH2: Sim | CL2: Aumentar a produção | CM2: Filhos continuarão com a produção de leite | CN2: Sim | CO2: PRONAMPE, Plano Safra | CR2: Sim | CT2: Sim | CW2: Utilizou crédito | DC2: Sim | DD2: 2000 | DE2: 2000 | DF2: 2000 | DG2: 31 | DH2: 28 | DI2: 34 | DJ2: 95 | DK2: 0 | DL2: 0 | DM2: 0.2 | DN2: 4.8 | DO2: 60 | DP2: 45 | DQ2: Sim | DR2: Sim | DS2: Sim | DT2: 0.21369863 | DU2: 6 | DV2: =DT2+DU2 -> 6.2136986 | DW2: 71 | DX2: 9 | DY2: 19 | DZ2: 1 | EA2: 22 | EB2: 34 | EC2: 1 | ED2: 0 | EE2: 2 | EF2: 0 | EG2: 0 | EH2: 0 | EI2: 0 | EJ2: 100 | EK2: 0 | EL2: 0 | EM2: 0 | EN2: 0 | EO2: 2 | EP2: 7 | EQ2: 63 | ER2: 28 | ES2: 0 | ET2: 0 | EU2: 0 | EV2: Tanque de expansão | EW2: Sim | EX2: Sim | EY2: Sala de ordenha com fosso | EZ2: Sim | FA2: Sim | FB2: Mecânica | FC2: 3 | FD2: 3 | FE2: Todos os dias | FF2: Mista | FG2: Brachiaria, Tifton | FH2: Sim | FO2: Sim | FQ2: Nenhuma das anteriores | FX2: Sim | FZ2: Proprietário(a) e família | GA2: Produção de leite, Produtividade | GB2: Sim | GC2: Sim | GI2: Utiliza os indicadores econômicos de forma sistemática para tomada de decisão | GJ2: Sim | GK2: 2.43 | GL2: Assistência técnica, Treinamento (curso, palestra, etc.), Outras mídias sociais | GM2: Sim | GO2: Sim | GR2: Sim | GS2: 150 | GT2: Alimentação do rebanho, Manejo do rebanho, Gerenciamento da produção | GX2: Sim | GZ2: Sim | HB2: Sim | HF2: Cálculo do custo de produção, Mercado do leite | HH2: Sim | HI2: Sim | HR2: 60 | HS2: 40 | HT2: 0 | HU2: 0 | HV2: 0 | HW2: Galpão coberto, Ventiladores mecânicos, Aspersores ou nebulizadores, Sistema de resfriamento evaporativo, Bebedouros, Controle automatizado de temperatura/umidade | HX2: Sim | IB2: Sim | ID2: Sim | IE2: Sim | IF2: Sim | IH2: Residência e locais de produção | II2: Em toda fazenda | IJ2: Balança para os animais, Trator, Vagão forrageiro, Ensiladeira, Misturador de ração | IL2: Sim | IM2: Sim | IN2: Sim | IR2: Sim | IT2: Sim | IU2: Chorumeira | IV2: Plantio direto, Cobertura do solo, Descarte adequado de embalagens (herbicida e defensivos), Tratamento de efluentes da residência | IW2: Sim | IX2: Sim | IY2: Sim | IZ2: Sim | JB2: 1 | JC2: 3 | JD2: 110 | JE2: 27 | JF2: 16 | JG2: 15 | JH2: 10 | JI2: Manqueira, Brucelose, Paratifo, Raiva, Enterotoxemia, Botulismo, Vermifugação, Carrapaticida, IBR/BVD, Leptospirose | JJ2: Sim | JK2: Sim | JL2: Sim | JM2: Sim | JN2: Sim | JO2: Sim | JP2: Sim | JQ2: Sim | JR2: Sim | JS2: Sim | JT2: Teste da caneca, Pré-dipping, Pós-dipping, Linha de ordenha, Alimentação após a ordenha, Identificação de animais tratados com antibiótico | JU2: Sim | JV2: Sim | JW2: Sim | JX2: Sim | JZ2: Sim | KA2: Sim | KB2: Inseminação artificial/IATF | KD2: Sim | KG2: Artificial | KH2: Idade e peso das novilhas | KI2: Ano todo | KJ2: Sim | KK2: Silagem de milho | KO2: Sim | KU2: 5 | KV2: 3.07 | KW2: 2.77 | KX2: 3.15 | KY2: Nível de CCS, Nível de CBT, Teor de gordura | LA2: Sim | LB2: Sim | LC2: Sim | LG2: Concorda | LH2: Concorda | LI2: Concorda | LJ2: Sim | LK2: Muito importante
B3: Coimbra | C3: Não familiar | D3: 4) 1001 a 2500 | E3: Fortemente acidentado | F3: Intensivo | G3: Alvenaria | H3: Alvenaria | I3: Alvenaria | J3: CAR - Cadastro Ambiental Rural, Cursos d’água/riacho/nascentes/mina, Vegetação nativa/mata/floresta, Área de preservação permanentes, Área de reserva legal, Serviço de água potável, Serviço de esgoto doméstico tratado, Serviço de telefonia | K3: Sim | L3: Sim | M3: Sim | N3: Sim | O3: Sim | P3: Sim | Q3: Sim | R3: Sim | S3: 62 | T3: 21 | U3: Masculino | V3: Ensino médio incompleto | W3: Na propriedade rural | X3: 40 | Y3: 60 | Z3: 0 | AA3: 0 | AB3: 0 | AC3: 0 | AD3: 5 | AE3: 95 | AF3: 0 | AG3: 0 | AH3: 0 | AI3: Não | AJ3: 5 | AK3: 5 | AL3: 30 | AM3: 60 | AN3: 0 | AO3: 50 | AP3: 50 | AQ3: 0 | AR3: Aposentadoria, PRONAMPE | AT3: Sim | AV3: Sim | BC3: Regular | BD3: Não | BE3: Por gostar, Por proporcionar renda mensal, Combina com outras explorações da propriedade | BF3: Sim | BH3: Sim | BJ3: Sim | BO3: Falta de mão de obra, Custo dos insumos, Instabilidade de políticas públicas | BP3: Sim | BU3: Sim | BW3: Sim | CB3: Mão de obra qualificada, Sanidade do rebanho, Preço do leite | CC3: Sim | CD3: Sim | CI3: Sim | CL3: Não sabe | CM3: Filhos deixarão o meio rural | CN3: Sim | CO3: PRONAMPE, Plano Safra | CR3: Sim | CT3: Sim | CW3: Utilizou crédito | DC3: Sim | DD3: 2500 | DE3: 2500 | DF3: 2500 | DG3: 19 | DH3: 19 | DI3: 19 | DJ3: 94.5 | DK3: 0 | DL3: 0 | DM3: 0.5 | DN3: 5 | DO3: 170 | DP3: 40 | DQ3: Sim | DR3: Sim | DS3: Não | DT3: 0.73972603 | DU3: 6 | DV3: =DT3+DU3 -> 6.739726 | DW3: 145 | DX3: 52 | DY3: 15 | DZ3: 6 | EA3: 46 | EB3: 114 | EC3: 0 | ED3: 0 | EE3: 4 | EF3: 0 | EG3: 0 | EH3: 40 | EI3: 0 | EJ3: 60 | EK3: 0 | EL3: 0 | EM3: 0 | EN3: 0 | EO3: 0 | EP3: 25 | EQ3: 25 | ER3: 50 | ES3: 0 | ET3: 0 | EU3: 0 | EV3: Tanque de expansão | EW3: Sim | EX3: Sim | EY3: Sala de ordenha com fosso | EZ3: Sim | FA3: Sim | FB3: Mecânica | FC3: 2 | FD3: 2 | FE3: Todos os dias | FF3: Plantada | FG3: Brachiaria, Tifton | FH3: Sim | FO3: Sim | FQ3: Controle de plantas invasoras, Rotação de pastagens, Divisão em piquetes, Cerca elétrica nos piquetes | FU3: Sim | FV3: Sim | FW3: Sim | FZ3: Administrador(a) e proprietário(a) | GA3: Produção de leite, Produtividade, Despesas | GB3: Sim | GC3: Sim | GE3: Sim | GI3: Utiliza os indicadores econômicos de forma sistemática para tomada de decisão | GJ3: Sim | GK3: 2.4 | GL3: Assistência técnica, Jornais e revistas agropecuários, Outras mídias sociais | GM3: Sim | GP3: Sim | GR3: Sim | GS3: 216 | GT3: Sanidade do rebanho, Melhoramento genético, Qualidade do leite | GY3: Sim | HA3: Sim | HD3: Sim | HF3: Mercado do leite, Produção de leite e meio ambiente | HI3: Sim | HO3: Sim | HR3: 0 | HS3: 100 | HT3: 0 | HU3: 0 | HV3: 0 | HW3: Galpão coberto, Ventiladores mecânicos, Bebedouros | HX3: Sim | IB3: Sim | IE3: Sim | IH3: Residência e locais de produção | II3: Em toda fazenda | IJ3: Trator, Vagão forrageiro, Plantadeira, Grade, Ensiladeira, Distribuidor de calcário, Misturador de ração | IM3: Sim | IN3: Sim | IO3: Sim | IP3: Sim | IR3: Sim | IS3: Sim | IT3: Sim | IU3: Chorumeira | IV3: Plantio direto, Cobertura do solo, Descarte adequado de embalagens (herbicida e defensivos), Tratamento de efluentes da residência, Rotação de culturas | IW3: Sim | IX3: Sim | IY3: Sim | IZ3: Sim | JA3: Sim | JB3: 1 | JC3: 3 | JD3: 100 | JE3: 24 | JF3: 12 | JG3: 5 | JH3: 2 | JI3: Manqueira, Brucelose, Paratifo, Raiva, Enterotoxemia, Botulismo, Vermifugação, Carrapaticida, IBR/BVD, Leptospirose | JJ3: Sim | JK3: Sim | JL3: Sim | JM3: Sim | JN3: Sim | JO3: Sim | JP3: Sim | JQ3: Sim | JR3: Sim | JS3: Sim | JT3: Teste da caneca, Pré-dipping, Pós-dipping, Alimentação após a ordenha, Identificação de animais tratados com antibiótico | JU3: Sim | JV3: Sim | JW3: Sim | JZ3: Sim | KA3: Sim | KB3: FIV/TE, Inseminação artificial/IATF | KC3: Sim | KD3: Sim | KG3: Artificial | KH3: Peso das novilhas | KI3: Ano todo | KJ3: Sim | KK3: Silagem de milho | KO3: Sim | KU3: 3 | KV3: 2.75 | KW3: 2.75 | KX3: 2.75 | KY3: Volume de leite entregue, Nível de CCS, Nível de CBT, Teor de gordura, Teor de proteína | KZ3: Sim | LA3: Sim | LB3: Sim | LC3: Sim | LD3: Sim | LG3: Concorda | LH3: Concorda | LI3: Concorda | LJ3: Sim | LK3: Muito importante
B4: Paula Cândido | C4: Familiar | D4: 2) 201 a 500 | E4: Fortemente acidentado | F4: Semiextensivo | G4: Alvenaria | H4: Não possui | I4: Madeira | J4: CAR - Cadastro Ambiental Rural, Cursos d’água/riacho/nascentes/mina, Vegetação nativa/mata/floresta, Área de preservação permanentes, Área de reserva legal, Serviço de água potável, Serviço de telefonia | K4: Sim | L4: Sim | M4: Sim | N4: Sim | O4: Sim | P4: Sim | R4: Sim | S4: 43 | T4: 20 | U4: Masculino | V4: Ensino médio completo | W4: Na propriedade rural | X4: 50 | Y4: 50 | Z4: 0 | AA4: 0 | AB4: 0 | AC4: 0 | AD4: 0 | AE4: 100 | AF4: 0 | AG4: 0 | AH4: 0 | AI4: Sim | AJ4: 95 | AK4: 0 | AL4: 0 | AM4: 0 | AN4: 5 | AO4: 90 | AP4: 10 | AQ4: 0 | AR4: Bolsa família, PRONAF | AS4: Sim | AU4: Sim | BC4: Regular | BD4: Sim | BE4: Por gostar, Por proporcionar renda mensal, Emprega a família | BF4: Sim | BH4: Sim | BM4: Sim | BO4: Falta de mão de obra | BP4: Sim | CB4: Mão de obra qualificada, Preço do leite | CC4: Sim | CI4: Sim | CL4: Continuar como está | CM4: Filhos continuarão com a produção de leite | CN4: Sim | CO4: PRONAF | CP4: Sim | CW4: Utilizou crédito | DC4: Sim | DD4: 500 | DE4: 500 | DF4: 500 | DG4: 22 | DH4: 22 | DI4: 22 | DJ4: 100 | DK4: 0 | DL4: 0 | DM4: 0 | DN4: 0 | DO4: 34 | DP4: 15 | DQ4: Sim | DR4: Sim | DS4: Não | DT4: 3.0575342 | DU4: 1 | DV4: =DT4+DU4 -> 4.0575342 | DW4: 22 | DX4: 8 | DY4: 4 | DZ4: 1 | EA4: 20 | EB4: 2 | EC4: 0 | ED4: 0 | EE4: 1 | EF4: 0 | EG4: 0 | EH4: 0 | EI4: 0 | EJ4: 100 | EK4: 0 | EL4: 0 | EM4: 0 | EN4: 0 | EO4: 0 | EP4: 0 | EQ4: 100 | ER4: 0 | ES4: 0 | ET4: 0 | EU4: 0 | EV4: Tanque de expansão | EW4: Sim | EX4: Sim | EY4: Sala de ordenha com fosso | EZ4: Sim | FA4: Sim | FB4: Mecânica | FC4: 2 | FD4: 2 | FE4: De 2 em 2 dias | FF4: Mista | FG4: Brachiaria | FH4: Sim | FQ4: Nenhuma das anteriores | FX4: Sim | FZ4: Apenas o(a) proprietário(a) | GA4: Produção de leite, Produtividade, Receitas, Despesas | GB4: Sim | GC4: Sim | GD4: Sim | GE4: Sim | GI4: Utiliza os indicadores econômicos de forma sistemática para tomada de decisão | GJ4: Sim | GK4: 2 | GL4: Assistência técnica, Vizinho, amigo ou parente | GM4: Sim | GN4: Sim | GS4: 24 | GT4: Planejamento da empresa rural, Alimentação do rebanho, Sanidade do rebanho | GU4: Sim | GX4: Sim | GY4: Sim | HF4: Não sabe | HQ4: Sim | HR4: 0 | HS4: 100 | HT4: 0 | HU4: 0 | HV4: 0 | HW4: Galpão coberto, Cobertura vegetal (árvores, sombra natural), Ventiladores mecânicos, Bebedouros | HX4: Sim | HZ4: Sim | IB4: Sim | IE4: Sim | IH4: Residência e locais de produção | II4: Somente na residência | IJ4: Picadeira, Trator, Plantadeira, Grade, Arado, Ensiladeira, Distribuidor de calcário, Misturador de ração | IK4: Sim | IM4: Sim | IO4: Sim | IP4: Sim | IQ4: Sim | IR4: Sim | IS4: Sim | IT4: Sim | IU4: “Raspado” e/ou armazenado | IV4: Plantio direto, Cobertura do solo, Descarte adequado de embalagens (herbicida e defensivos) | IW4: Sim | IX4: Sim | IY4: Sim | JB4: 0 | JC4: 3 | JD4: 100 | JE4: 26 | JF4: 13 | JG4: 0 | JH4: 2 | JI4: Manqueira, Brucelose, Paratifo, Raiva, Enterotoxemia, Botulismo, Vermifugação, Carrapaticida, IBR/BVD, Leptospirose | JJ4: Sim | JK4: Sim | JL4: Sim | JM4: Sim | JN4: Sim | JO4: Sim | JP4: Sim | JQ4: Sim | JR4: Sim | JS4: Sim | JT4: Pré-dipping, Pós-dipping, Linha de ordenha | JV4: Sim | JW4: Sim | JX4: Sim | KB4: FIV/TE, Inseminação artificial/IATF | KC4: Sim | KD4: Sim | KG4: Artificial | KH4: Idade e peso das novilhas | KI4: Ano todo | KJ4: Sim | KK4: Silagem de milho | KO4: Sim | KU4: 5 | KV4: 2.8 | KW4: 1.8 | KX4: 3 | KY4: Volume de leite entregue, Nível de CCS, Nível de CBT, Teor de gordura, Teor de proteína | KZ4: Sim | LA4: Sim | LB4: Sim | LC4: Sim | LD4: Sim | LG4: Concorda | LH4: Concorda | LI4: Concorda | LJ4: Sim | LK4: Muito importante
B5: Paula Cândido | C5: Familiar | D5: 1) Até 200 | E5: Fortemente acidentado | F5: Semiextensivo | G5: Alvenaria | H5: Não possui | I5: Mista | J5: CAR - Cadastro Ambiental Rural, Cursos d’água/riacho/nascentes/mina, Vegetação nativa/mata/floresta, Área de preservação permanentes, Área de reserva legal, Serviço de água potável, Serviço de telefonia | K5: Sim | L5: Sim | M5: Sim | N5: Sim | O5: Sim | P5: Sim | R5: Sim | S5: 27 | T5: 7 | U5: Masculino | V5: Ensino médio completo | W5: Na cidade | X5: 100 | Y5: 0 | Z5: 0 | AA5: 0 | AB5: 0 | AC5: 0 | AD5: 100 | AE5: 0 | AF5: 0 | AG5: 0 | AH5: 0 | AI5: Sim | AJ5: 50 | AK5: 50 | AL5: 0 | AM5: 0 | AN5: 0 | AO5: 60 | AP5: 40 | AQ5: 0 | AR5: Não recebe benefício do governo | BB5: Sim | BC5: Regular | BD5: Sim | BE5: Por proporcionar renda mensal, Tem mercado garantido | BH5: Sim | BK5: Sim | BO5: Instabilidade de políticas públicas | BW5: Sim | CB5: Qualidade genética dos animais, Alimentação do rebanho, Preço do leite | CE5: Sim | CF5: Sim | CI5: Sim | CL5: Aumentar a produção | CM5: Filhos continuarão com a produção de leite | CN5: Não | CO5: Não utilizou crédito | CV5: Sim | CW5: Não tem capacidade para endividamento | CZ5: Sim | DD5: 130 | DE5: 130 | DF5: 130 | DG5: 19.666667 | DH5: 18 | DI5: 22 | DJ5: 100 | DK5: 0 | DL5: 0 | DM5: 0 | DN5: 0 | DO5: 34 | DP5: 10 | DQ5: Sim | DR5: Sim | DS5: Não | DT5: 0.50958904 | DU5: 0 | DV5: =DT5+DU5 -> 0.50958904 | DW5: 5 | DX5: 2 | DY5: 0 | DZ5: 0 | EA5: 3 | EB5: 1 | EC5: 0 | ED5: 0 | EE5: 1 | EF5: 0 | EG5: 0 | EH5: 0 | EI5: 0 | EJ5: 50 | EK5: 0 | EL5: 50 | EM5: 0 | EN5: 0 | EO5: 80 | EP5: 20 | EQ5: 0 | ER5: 0 | ES5: 0 | ET5: 0 | EU5: 0 | EV5: Tanque de expansão | EW5: Sim | EX5: Sim | EY5: Sala de ordenha com fosso | EZ5: Sim | FA5: Sim | FB5: Mecânica | FC5: 2 | FD5: 2 | FE5: De 2 em 2 dias | FF5: Plantada | FG5: Brachiaria, Panicum, Tifton | FH5: Sim | FI5: Sim | FO5: Sim | FQ5: Correção e adubação do solo na implantação, Adubação anual de cobertura, Controle de plantas invasoras, Rotação de pastagens, Divisão em piquetes, Cerca elétrica nos piquetes | FR5: Sim | FU5: Sim | FV5: Sim | FW5: Sim | FZ5: Apenas o(a) proprietário(a) | GA5: Produção de leite, Produtividade, Receitas, Despesas | GB5: Sim | GC5: Sim | GD5: Sim | GE5: Sim | GI5: Utiliza os indicadores econômicos de forma sistemática para tomada de decisão | GJ5: Sim | GK5: 2 | GL5: Assistência técnica, Vizinho, amigo ou parente, Treinamento (curso, palestra, etc.), Jornais e revistas agropecuários, Outras mídias sociais | GM5: Sim | GN5: Sim | GO5: Sim | GP5: Sim | GR5: Sim | GS5: 28 | GT5: Planejamento da empresa rural, Cálculo do custo de produção, Manejo do rebanho | GU5: Sim | GV5: Sim | GZ5: Sim | HF5: Mercado do leite | HI5: Sim | HR5: 0 | HS5: 0 | HT5: 50 | HU5: 50 | HV5: 0 | HW5: Cobertura vegetal (árvores, sombra natural), Ventiladores mecânicos, Aspersores ou nebulizadores, Bebedouros | HZ5: Sim | IB5: Sim | IE5: Sim | IH5: Residência e locais de produção | II5: Somente na residência | IJ5: Misturador de ração | IT5: Sim | IU5: “Raspado” e/ou armazenado | IV5: Plantio direto, Cobertura do solo, Descarte adequado de embalagens (herbicida e defensivos), Rotação de culturas | IW5: Sim | IX5: Sim | IY5: Sim | JA5: Sim | JB5: 0 | JC5: 3 | JD5: 110 | JE5: 27 | JF5: 14 | JG5: 0 | JH5: 0 | JI5: Manqueira, Brucelose, Paratifo, Raiva, Enterotoxemia, Botulismo, Vermifugação, Carrapaticida, IBR/BVD, Leptospirose | JJ5: Sim | JK5: Sim | JL5: Sim | JM5: Sim | JN5: Sim | JO5: Sim | JP5: Sim | JQ5: Sim | JR5: Sim | JS5: Sim | JT5: Teste da caneca, Pré-dipping, Pós-dipping, Linha de ordenha, Alimentação durante a ordenha, Alimentação após a ordenha | JU5: Sim | JV5: Sim | JW5: Sim | JX5: Sim | JY5: Sim | JZ5: Sim | KB5: Inseminação artificial/IATF | KD5: Sim | KG5: Artificial | KH5: Idade e peso das novilhas | KI5: Ano todo | KJ5: Sim | KK5: Silagem de milho | KO5: Sim | KU5: 4 | KV5: 2.52 | KW5: 2.2 | KX5: 2.8 | KY5: Nível de CCS, Nível de CBT, Teor de gordura, Teor de proteína | LA5: Sim | LB5: Sim | LC5: Sim | LD5: Sim | LG5: Concorda | LH5: Concorda | LI5: Concorda | LJ5: Sim | LK5: Muito importante
B6: Cajuri | C6: Não familiar | D6: 5) Acima de 2501 | E6: Suavemente acidentado ou acidentado | F6: Intensivo | G6: Mista | H6: Mista | I6: Madeira | J6: CAR - Cadastro Ambiental Rural, Cursos d’água/riacho/nascentes/mina, Vegetação nativa/mata/floresta, Área de preservação permanentes, Área de reserva legal, Serviço de água potável | K6: Sim | L6: Sim | M6: Sim | N6: Sim | O6: Sim | P6: Sim | S6: 66 | T6: 50 | U6: Masculino | V6: Ensino médio completo | W6: Na propriedade rural | X6: 23 | Y6: 77 | Z6: 0 | AA6: 0 | AB6: 0 | AC6: 0 | AD6: 50 | AE6: 50 | AF6: 0 | AG6: 0 | AH6: 0 | AI6: Não | AJ6: 90 | AK6: 0 | AL6: 10 | AM6: 0 | AN6: 0 | AO6: 90 | AP6: 10 | AQ6: 0 | AR6: Não recebe benefício do governo | BB6: Sim | BC6: Bom | BD6: Sim | BE6: Por ser uma atividade lucrativa | BG6: Sim | BO6: Falta de mão de obra, Deficiência na qualificação da mão de obra, Falta de crédito rural, com taxas de juros compatíveis com a atividade | BP6: Sim | BQ6: Sim | BR6: Sim | CB6: Mão de obra qualificada, Sanidade do rebanho, Alimentação do rebanho | CC6: Sim | CD6: Sim | CF6: Sim | CL6: Aumentar a produção | CM6: Filhos continuarão com a produção de leite | CN6: Não | CO6: Não utilizou crédito | CV6: Sim | CW6: Não precisou de crédito | DB6: Sim | DD6: 10000 | DE6: 9000 | DF6: 11000 | DG6: 28 | DH6: 26 | DI6: 30 | DJ6: 95 | DK6: 0 | DL6: 0 | DM6: 0 | DN6: 5 | DO6: 200 | DP6: 70 | DQ6: Sim | DR6: Sim | DS6: Sim | DT6: 1.6109589 | DU6: 18 | DV6: =DT6+DU6 -> 19.610959 | DW6: 400 | DX6: 80 | DY6: 70 | DZ6: 20 | EA6: 200 | EB6: 150 | EC6: 0 | ED6: 2 | EE6: 3 | EF6: 0 | EG6: 0 | EH6: 0 | EI6: 0 | EJ6: 100 | EK6: 0 | EL6: 0 | EM6: 0 | EN6: 0 | EO6: 0 | EP6: 0 | EQ6: 0 | ER6: 100 | ES6: 0 | ET6: 0 | EU6: 0 | EV6: Tanque de expansão | EW6: Sim | EX6: Sim | EY6: Sala de ordenha com fosso | EZ6: Sim | FA6: Sim | FB6: Mecânica | FC6: 2 | FD6: 2 | FE6: Todos os dias | FF6: Plantada | FG6: Cynodon | FN6: Sim | FQ6: Correção e adubação do solo na implantação | FR6: Sim | FZ6: Apenas o(a) proprietário(a) | GA6: Produção de leite, Produtividade, Receitas | GB6: Sim | GC6: Sim | GD6: Sim | GI6: Utiliza os indicadores econômicos de forma sistemática para tomada de decisão | GJ6: Sim | GK6: 2.6 | GL6: Assistência técnica | GM6: Sim | GS6: 120 | GT6: Planejamento da empresa rural, Cálculo do custo de produção, Sanidade do rebanho | GU6: Sim | GV6: Sim | GY6: Sim | HF6: Gerenciamento da produção | HN6: Sim | HR6: 30 | HS6: 70 | HT6: 0 | HU6: 0 | HV6: 0 | HW6: Galpão coberto, Ventiladores mecânicos, Sistema de resfriamento evaporativo, Bebedouros, Controle automatizado de temperatura/umidade | HX6: Sim | IB6: Sim | ID6: Sim | IE6: Sim | IF6: Sim | IH6: Residência e locais de produção | II6: Em toda fazenda | IJ6: Balança para os animais, Trator, Vagão forrageiro, Plantadeira, Grade, Ensiladeira, Distribuidor de calcário, Misturador de ração | IL6: Sim | IM6: Sim | IN6: Sim | IO6: Sim | IP6: Sim | IR6: Sim | IS6: Sim | IT6: Sim | IU6: Não tem destino certo | IV6: Plantio direto, Cobertura do solo, Descarte adequado de embalagens (herbicida e defensivos), Rotação de culturas | IW6: Sim | IX6: Sim | IY6: Sim | JA6: Sim | JB6: 3 | JC6: 3 | JD6: 120 | JE6: 23 | JF6: 14 | JG6: 3 | JH6: 3 | JI6: Manqueira, Brucelose, Paratifo, Raiva, Enterotoxemia, Vermifugação, Carrapaticida, IBR/BVD, Leptospirose | JJ6: Sim | JK6: Sim | JL6: Sim | JM6: Sim | JN6: Sim | JP6: Sim | JQ6: Sim | JR6: Sim | JS6: Sim | JT6: Teste da caneca, Pré-dipping, Pós-dipping, Linha de ordenha, Alimentação após a ordenha, Identificação de animais tratados com antibiótico | JU6: Sim | JV6: Sim | JW6: Sim | JX6: Sim | JZ6: Sim | KA6: Sim | KB6: Inseminação artificial/IATF | KD6: Sim | KG6: Artificial | KH6: Idade e peso das novilhas | KI6: Ano todo | KJ6: Sim | KK6: Silagem de milho | KO6: Sim | KU6: 8 | KV6: 2.76 | KW6: 2.4 | KX6: 3 | KY6: Volume de leite entregue, Nível de CCS, Nível de CBT, Teor de gordura, Teor de proteína | KZ6: Sim | LA6: Sim | LB6: Sim | LC6: Sim | LD6: Sim | LG6: Concorda | LH6: Concorda | LI6: Concorda | LJ6: Sim | LK6: Muito importante
B7: Cajuri | C7: Familiar | D7: 3) 501 a 1000 | E7: Extremamente acidentado | F7: Intensivo | G7: Alvenaria | H7: Não possui | I7: Alvenaria | J7: CAR - Cadastro Ambiental Rural, Cursos d’água/riacho/nascentes/mina, Vegetação nativa/mata/floresta, Área de preservação permanentes, Área de reserva legal, Serviço de telefonia | K7: Sim | L7: Sim | M7: Sim | N7: Sim | O7: Sim | R7: Sim | S7: 50 | T7: 15 | U7: Masculino | V7: Ensino fundamental incompleto | W7: Na propriedade rural | X7: 0 | Y7: 0 | Z7: 0 | AA7: 100 | AB7: 0 | AC7: 0 | AI7: Não | AJ7: 90 | AK7: 0 | AL7: 0 | AM7: 0 | AN7: 10 | AO7: 99 | AP7: 1 | AQ7: 0 | AR7: PRONAF | AU7: Sim | BC7: Muito bom | BD7: Sim | BE7: Por gostar, Por ser uma atividade lucrativa, Por proporcionar renda mensal | BF7: Sim | BG7: Sim | BH7: Sim | BO7: Deficiência de informações de mercado | BT7: Sim | CB7: Qualidade genética dos animais, Alimentação do rebanho, Reprodução do rebanho | CE7: Sim | CF7: Sim | CH7: Sim | CL7: Aumentar a produção | CM7: Não sabe | CN7: Sim | CO7: PRONAF | CP7: Sim | CW7: Utilizou crédito | DC7: Sim | DD7: 733.33333 | DE7: 650 | DF7: 750 | DG7: 31.333333 | DH7: 28 | DI7: 32 | DJ7: 96 | DK7: 0 | DL7: 1 | DM7: 1 | DN7: 2 | DP7: 6.2 | DQ7: Sim | DR7: Sim | DS7: Sim | DT7: 1.0001096 | DU7: 0 | DV7: =DT7+DU7 -> 1.0001096 | DW7: 28 | DX7: 4 | DY7: 2 | DZ7: 1 | EA7: 19 | EB7: 13 | EC7: 1 | ED7: 0 | EE7: 0 | EF7: 0 | EG7: 100 | EH7: 0 | EI7: 0 | EJ7: 0 | EK7: 0 | EL7: 0 | EM7: 0 | EN7: 0 | EO7: 0 | EP7: 10 | EQ7: 90 | ER7: 0 | ES7: 0 | ET7: 0 | EU7: 0 | EV7: Tanque de expansão | EW7: Sim | EX7: Sim | EY7: Sala de ordenha com fosso | EZ7: Sim | FA7: Sim | FB7: Mecânica | FC7: 2 | FD7: 2 | FE7: De 2 em 2 dias | FF7: Plantada | FG7: Brachiaria, Tifton | FH7: Sim | FO7: Sim | FQ7: Controle de plantas invasoras, Divisão em piquetes, Cerca elétrica nos piquetes | FV7: Sim | FW7: Sim | FZ7: Apenas o(a) proprietário(a) | GA7: Produtividade, Receitas | GC7: Sim | GD7: Sim | GI7: Utiliza os indicadores econômicos de forma sistemática para tomada de decisão | GJ7: Sim | GK7: 2.35 | GL7: Assistência técnica, Outras mídias sociais | GM7: Sim | GR7: Sim | GS7: 20 | GT7: Planejamento da empresa rural, Alimentação do rebanho, Qualidade do leite | GU7: Sim | GX7: Sim | HD7: Sim | HF7: Mercado do leite | HI7: Sim | HR7: 0 | HS7: 100 | HT7: 0 | HU7: 0 | HV7: 0 | HW7: Galpão coberto, Cobertura vegetal (árvores, sombra natural), Ventiladores mecânicos, Aspersores ou nebulizadores, Bebedouros, Controle automatizado de temperatura/umidade | HX7: Sim | HZ7: Sim | IB7: Sim | IE7: Sim | IF7: Sim | IH7: Residência e locais de produção | II7: Somente na residência | IJ7: Trator, Plantadeira, Grade, Ensiladeira, Misturador de ração | IM7: Sim | IO7: Sim | IP7: Sim | IR7: Sim | IT7: Sim | IU7: Não tem destino certo | IV7: Rotação de culturas | JA7: Sim | JB7: 0 | JC7: 2.5 | JD7: 120 | JE7: 24 | JF7: 14 | JG7: 0 | JH7: 0 | JI7: Manqueira, Brucelose, Raiva, Botulismo, Vermifugação, IBR/BVD, Leptospirose | JJ7: Sim | JK7: Sim | JM7: Sim | JO7: Sim | JP7: Sim | JR7: Sim | JS7: Sim | JT7: Pré-dipping, Pós-dipping, Linha de ordenha | JV7: Sim | JW7: Sim | JX7: Sim | KB7: Inseminação artificial/IATF, Natural não controlada | KD7: Sim | KF7: Sim | KG7: Artificial | KH7: Não tem critério definido | KI7: Ano todo | KJ7: Sim | KK7: Silagem de milho | KO7: Sim | KU7: 5 | KV7: 3.04 | KW7: 2.8 | KX7: 2.8 | KY7: Volume de leite entregue, Nível de CCS, Nível de CBT, Teor de gordura, Teor de proteína | KZ7: Sim | LA7: Sim | LB7: Sim | LC7: Sim | LD7: Sim | LG7: Concorda | LH7: Concorda | LI7: Concorda | LJ7: Sim | LK7: Pouco importante
B8: Presidente Bernardes | C8: Não familiar | D8: 4) 1001 a 2500 | E8: Suavemente acidentado ou acidentado | F8: Intensivo | G8: Alvenaria | H8: Não possui | I8: Alvenaria | J8: CAR - Cadastro Ambiental Rural, Cursos d’água/riacho/nascentes/mina, Vegetação nativa/mata/floresta, Área de preservação permanentes | K8: Sim | L8: Sim | M8: Sim | N8: Sim | S8: 31 | T8: 19 | U8: Masculino | V8: Ensino médio completo | W8: Na propriedade rural | X8: 99 | Y8: 1 | Z8: 0 | AA8: 0 | AB8: 0 | AC8: 0 | AD8: 10 | AE8: 90 | AF8: 0 | AG8: 0 | AH8: 0 | AI8: Não | AJ8: 40 | AK8: 0 | AL8: 0 | AM8: 0 | AN8: 60 | AO8: 90 | AP8: 10 | AQ8: 0 | AR8: Não recebe benefício do governo | BB8: Sim | BC8: Muito bom | BD8: Sim | BE8: Por gostar, Por ser uma atividade lucrativa, Por proporcionar renda mensal | BF8: Sim | BG8: Sim | BH8: Sim | BO8: Falta de mão de obra, Deficiência na qualificação da mão de obra, Custo dos insumos | BP8: Sim | BQ8: Sim | BU8: Sim | CB8: Sanidade do rebanho, Qualidade genética dos animais, Preço do leite | CD8: Sim | CE8: Sim | CI8: Sim | CL8: Continuar como está | CM8: Filhos continuarão com a produção de leite | CN8: Não | CO8: Não utilizou crédito | CV8: Sim | CW8: Não precisou de crédito | DB8: Sim | DD8: 1613.3333 | DE8: 1600 | DF8: 1620 | DG8: 31.333333 | DH8: 30 | DI8: 32 | DJ8: 80 | DK8: 1 | DL8: 0 | DM8: 2 | DN8: 17 | DO8: 46 | DP8: 17 | DQ8: Não | DR8: Não | DS8: Não | DT8: 0.49315068 | DU8: 11 | DV8: =DT8+DU8 -> 11.493151 | DW8: 53 | DX8: 9 | DY8: 19 | DZ8: 0 | EA8: 35 | EB8: 15 | EC8: 0 | ED8: 0 | EE8: 0 | EF8: 0 | EG8: 0 | EH8: 0 | EI8: 0 | EJ8: 95 | EK8: 0 | EL8: 5 | EM8: 0 | EN8: 0 | EO8: 1 | EP8: 0 | EQ8: 0 | ER8: 99 | ES8: 0 | ET8: 0 | EU8: 0 | EV8: Tanque de expansão | EW8: Sim | EX8: Sim | EY8: Sala de ordenha com fosso | EZ8: Sim | FA8: Sim | FB8: Mecânica | FC8: 2 | FD8: 2 | FE8: De 2 em 2 dias | FF8: Não tem pastagem | FG8: Não tem pastagem plantada | FP8: Sim | FQ8: Não utiliza pastagens | FY8: Sim | FZ8: Proprietário(a) e família | GA8: Produtividade, Venda de genética, Venda de animais | GC8: Sim | GF8: Sim | GG8: Sim | GI8: Utiliza os indicadores econômicos de forma sistemática para tomada de decisão | GJ8: Não | GL8: Assistência técnica, Treinamento (curso, palestra, etc.), Outras mídias sociais | GM8: Sim | GO8: Sim | GR8: Sim | GS8: 26 | GT8: Sanidade do rebanho, Manejo do rebanho, Melhoramento genético | GY8: Sim | GZ8: Sim | HA8: Sim | HF8: Mercado do leite | HI8: Sim | HR8: 0 | HS8: 100 | HT8: 0 | HU8: 0 | HV8: 0 | HW8: Galpão coberto, Ventiladores mecânicos, Aspersores ou nebulizadores, Sistema de resfriamento evaporativo, Bebedouros | HX8: Sim | IB8: Sim | ID8: Sim | IE8: Sim | IH8: Residência e locais de produção | II8: Em toda fazenda | IJ8: Picadeira, Balança para os animais, Trator, Vagão forrageiro, Grade, Misturador de ração | IK8: Sim | IL8: Sim | IM8: Sim | IN8: Sim | IP8: Sim | IT8: Sim | IU8: Chorumeira | IV8: Plantio direto, Cobertura do solo, Descarte adequado de embalagens (herbicida e defensivos), Tratamento de efluentes da residência, Rotação de culturas | IW8: Sim | IX8: Sim | IY8: Sim | IZ8: Sim | JA8: Sim | JB8: 0 | JC8: 3 | JD8: 110 | JE8: 23 | JF8: 13 | JG8: 1 | JH8: 1.6 | JI8: Manqueira, Brucelose, Raiva, Enterotoxemia, Botulismo, Vermifugação, Carrapaticida, IBR/BVD, Leptospirose | JJ8: Sim | JK8: Sim | JM8: Sim | JN8: Sim | JO8: Sim | JP8: Sim | JQ8: Sim | JR8: Sim | JS8: Sim | JT8: Teste da caneca, Pré-dipping, Pós-dipping, Alimentação após a ordenha, Identificação de animais tratados com antibiótico | JU8: Sim | JV8: Sim | JW8: Sim | JZ8: Sim | KA8: Sim | KB8: FIV/TE, Inseminação artificial/IATF | KC8: Sim | KD8: Sim | KG8: Natural | KH8: Idade e peso das novilhas | KI8: Ano todo | KJ8: Sim | KK8: Cana-de-açúcar, Capineira, Silagem de milho | KL8: Sim | KM8: Sim | KO8: Sim | KU8: 5 | KV8: 3 | KW8: 2.5 | KX8: 2.95 | KY8: Nível de CCS, Nível de CBT, Teor de gordura, Teor de proteína | LA8: Sim | LB8: Sim | LC8: Sim | LD8: Sim | LG8: Concorda | LH8: Concorda | LI8: Concorda | LJ8: Não | LK8: Muito importante
B9: Coimbra | C9: Não familiar | D9: 3) 501 a 1000 | E9: Suavemente acidentado ou acidentado | F9: Intensivo | G9: Alvenaria | H9: Alvenaria | I9: Mista | J9: CAR - Cadastro Ambiental Rural, Cursos d’água/riacho/nascentes/mina, Vegetação nativa/mata/floresta, Área de preservação permanentes, Área de reserva legal, Serviço de água potável | K9: Sim | L9: Sim | M9: Sim | N9: Sim | O9: Sim | P9: Sim | S9: 60 | T9: 5 | U9: Masculino | V9: Ensino médio completo | W9: Na cidade | X9: 70 | Y9: 30 | Z9: 0 | AA9: 0 | AB9: 0 | AC9: 0 | AD9: 0 | AE9: 100 | AF9: 0 | AG9: 0 | AH9: 0 | AI9: Não | AJ9: 50 | AK9: 0 | AL9: 0 | AM9: 0 | AN9: 50 | AO9: 97 | AP9: 3 | AQ9: 0 | AR9: Aposentadoria | AT9: Sim | BC9: Regular | BD9: Não | BE9: Por gostar, A atividade leiteira é uma tradição na família | BF9: Sim | BI9: Sim | BO9: Deficiência na qualificação da mão de obra, Falta de crédito rural, com taxas de juros compatíveis com a atividade, Custo dos insumos | BQ9: Sim | BR9: Sim | BU9: Sim | CB9: Mão de obra qualificada, Qualidade genética dos animais, Manejo do rebanho | CC9: Sim | CE9: Sim | CG9: Sim | CL9: Aumentar a produção | CM9: Filhos continuarão com a produção de leite | CN9: Sim | CO9: PRONAMPE | CR9: Sim | CW9: Utilizou crédito | DC9: Sim | DD9: 800 | DE9: 800 | DF9: 800 | DG9: 27 | DH9: 27 | DI9: 27 | DJ9: 95 | DK9: 0 | DL9: 0 | DM9: 0.5 | DN9: 4.5 | DO9: 15 | DP9: 25 | DQ9: Sim | DR9: Sim | DS9: Sim | DT9: 0.032876712 | DU9: 3 | DV9: =DT9+DU9 -> 3.0328767 | DW9: 38 | DX9: 3 | DY9: 10 | DZ9: 0 | EA9: 20 | EB9: 10 | EC9: 1 | ED9: 0 | EE9: 1 | EF9: 0 | EG9: 0 | EH9: 5 | EI9: 0 | EJ9: 95 | EK9: 0 | EL9: 0 | EM9: 0 | EN9: 0 | EO9: 5 | EP9: 90 | EQ9: 0 | ER9: 5 | ES9: 0 | ET9: 0 | EU9: 0 | EV9: Tanque de expansão | EW9: Sim | EX9: Sim | EY9: Sala de ordenha com fosso | EZ9: Sim | FA9: Sim | FB9: Mecânica | FC9: 2 | FD9: 2 | FE9: De 2 em 2 dias | FF9: Plantada | FG9: Brachiaria, Tifton | FH9: Sim | FO9: Sim | FQ9: Correção e adubação do solo na implantação, Controle de plantas invasoras, Rotação de pastagens, Divisão em piquetes | FR9: Sim | FU9: Sim | FV9: Sim | FZ9: Proprietário(a) e família | GA9: Produção de leite, Produtividade | GB9: Sim | GC9: Sim | GI9: Acompanha o fluxo de caixa e calcula periodicamente custos de produção e margens | GJ9: Sim | GK9: 2.48 | GL9: Assistência técnica, Treinamento (curso, palestra, etc.), Outras mídias sociais | GM9: Sim | GO9: Sim | GR9: Sim | GS9: 25 | GT9: Cálculo do custo de produção, Alimentação do rebanho, Sanidade do rebanho | GV9: Sim | GX9: Sim | GY9: Sim | HF9: Mercado do leite, Produção de leite e meio ambiente | HI9: Sim | HO9: Sim | HR9: 0 | HS9: 100 | HT9: 0 | HU9: 0 | HV9: 0 | HW9: Galpão coberto, Sombrite ou tela de sombreamento, Cobertura vegetal (árvores, sombra natural), Ventiladores mecânicos, Aspersores ou nebulizadores, Sistema de resfriamento evaporativo, Bebedouros | HX9: Sim | HY9: Sim | HZ9: Sim | IB9: Sim | ID9: Sim | IE9: Sim | IH9: Residência e locais de produção | II9: Em toda fazenda | IJ9: Picadeira, Trator, Misturador de ração | IK9: Sim | IM9: Sim | IT9: Sim | IU9: “Raspado” e/ou armazenado | IV9: Cobertura do solo, Descarte adequado de embalagens (herbicida e defensivos) | IX9: Sim | IY9: Sim | JB9: 0 | JC9: 3 | JD9: 110 | JE9: 23 | JF9: 13 | JG9: 3 | JH9: 6 | JI9: Manqueira, Brucelose, Raiva, Enterotoxemia, Botulismo, Vermifugação, Carrapaticida, IBR/BVD, Leptospirose | JJ9: Sim | JK9: Sim | JM9: Sim | JN9: Sim | JO9: Sim | JP9: Sim | JQ9: Sim | JR9: Sim | JS9: Sim | JT9: Teste da caneca, Pré-dipping, Pós-dipping, Alimentação após a ordenha, Identificação de animais tratados com antibiótico | JU9: Sim | JV9: Sim | JW9: Sim | JZ9: Sim | KA9: Sim | KB9: Inseminação artificial/IATF | KD9: Sim | KG9: Artificial | KH9: Idade e peso das novilhas | KI9: Ano todo | KJ9: Sim | KK9: Capineira, Silagem de milho | KM9: Sim | KO9: Sim | KU9: 0.6 | KV9: 2.75 | KW9: 2.3 | KX9: 2.5 | KY9: Volume de leite entregue, Nível de CCS, Nível de CBT, Teor de gordura, Teor de proteína | KZ9: Sim | LA9: Sim | LB9: Sim | LC9: Sim | LD9: Sim | LG9: Concorda | LH9: Concorda | LI9: Concorda | LJ9: Não | LK9: Pouco importante
B10: Teixeiras | C10: Não familiar | D10: 4) 1001 a 2500 | E10: Fortemente acidentado | F10: Intensivo | G10: Alvenaria | H10: Alvenaria | I10: Madeira | J10: CAR - Cadastro Ambiental Rural, Cursos d’água/riacho/nascentes/mina, Vegetação nativa/mata/floresta, Área de preservação permanentes, Área de reserva legal, Serviço de telefonia | K10: Sim | L10: Sim | M10: Sim | N10: Sim | O10: Sim | R10: Sim | S10: 60 | T10: 24 | U10: Masculino | V10: Ensino médio completo | W10: Na cidade | X10: 60 | Y10: 40 | Z10: 0 | AA10: 0 | AB10: 0 | AC10: 0 | AD10: 90 | AE10: 10 | AF10: 0 | AG10: 0 | AH10: 0 | AI10: Não | AJ10: 10 | AK10: 0 | AL10: 0 | AM10: 0 | AN10: 90 | AO10: 95 | AP10: 5 | AQ10: 0 | AR10: Não recebe benefício do governo | BB10: Sim | BC10: Bom | BD10: Sim | BE10: Por gostar | BF10: Sim | BO10: Deficiência na qualificação da mão de obra | BQ10: Sim | CB10: Mão de obra qualificada, Sanidade do rebanho, Qualidade genética dos animais | CC10: Sim | CD10: Sim | CE10: Sim | CL10: Aumentar a produção | CM10: Filhos continuarão com a produção de leite | CN10: Não | CO10: Não utilizou crédito | CV10: Sim | CW10: Documentação pessoal incompleta, Não precisou de crédito | CX10: Sim | DB10: Sim | DD10: 1300 | DE10: 1300 | DF10: 1300 | DG10: 22 | DH10: 22 | DI10: 22 | DJ10: 94 | DK10: 0 | DL10: 0 | DM10: 0 | DN10: 6 | DO10: 80.6 | DP10: 50 | DQ10: Sim | DR10: Sim | DS10: Não | DT10: 0.098630137 | DU10: 5 | DV10: =DT10+DU10 -> 5.0986301 | DW10: 64 | DX10: 14 | DY10: 8 | DZ10: 2 | EA10: 47 | EB10: 22 | EC10: 12 | ED10: 0 | EE10: 0 | EF10: 0 | EG10: 0 | EH10: 0 | EI10: 100 | EJ10: 0 | EK10: 0 | EL10: 0 | EM10: 0 | EN10: 0 | EO10: 0 | EP10: 80 | EQ10: 20 | ER10: 0 | ES10: 0 | ET10: 0 | EU10: 0 | EV10: Tanque de expansão | EW10: Sim | EX10: Sim | EY10: Sala de ordenha com fosso | EZ10: Sim | FA10: Sim | FB10: Mecânica | FC10: 2 | FD10: 2 | FE10: De 2 em 2 dias | FF10: Plantada | FG10: Brachiaria | FH10: Sim | FQ10: Correção e adubação do solo na implantação, Controle de plantas invasoras, Rotação de pastagens, Divisão em piquetes | FR10: Sim | FU10: Sim | FV10: Sim | FZ10: Apenas o(a) proprietário(a) | GA10: Produção de leite, Produtividade, Receitas | GB10: Sim | GC10: Sim | GD10: Sim | GI10: Acompanha o fluxo de caixa e calcula periodicamente custos de produção e margens | GJ10: Sim | GK10: 2.21 | GL10: Assistência técnica | GM10: Sim | GS10: 84 | GT10: Cálculo do custo de produção, Alimentação do rebanho, Sanidade do rebanho, Melhoramento genético | GV10: Sim | GX10: Sim | GY10: Sim | HA10: Sim | HF10: Mercado do leite | HI10: Sim | HR10: 0 | HS10: 100 | HT10: 0 | HU10: 0 | HV10: 0 | HW10: Galpão coberto, Ventiladores mecânicos, Bebedouros | HX10: Sim | IB10: Sim | IE10: Sim | IH10: Residência e locais de produção | II10: Em toda fazenda | IJ10: Picadeira, Trator, Vagão forrageiro, Plantadeira, Grade, Ensiladeira, Misturador de ração | IK10: Sim | IM10: Sim | IN10: Sim | IO10: Sim | IP10: Sim | IR10: Sim | IT10: Sim | IU10: Chorumeira | IV10: Plantio direto, Cobertura do solo | IW10: Sim | IX10: Sim | JB10: 1 | JC10: 2.5 | JD10: 120 | JE10: 29.6 | JF10: 15.5 | JG10: 3 | JH10: 3 | JI10: Manqueira, Brucelose, Raiva, Enterotoxemia, Vermifugação, Carrapaticida, IBR/BVD, Leptospirose | JJ10: Sim | JK10: Sim | JM10: Sim | JN10: Sim | JP10: Sim | JQ10: Sim | JR10: Sim | JS10: Sim | JT10: Teste da caneca, Pré-dipping, Pós-dipping, Linha de ordenha, Alimentação durante a ordenha | JU10: Sim | JV10: Sim | JW10: Sim | JX10: Sim | JY10: Sim | KB10: FIV/TE, Inseminação artificial/IATF | KC10: Sim | KD10: Sim | KG10: Artificial | KH10: Idade e peso das novilhas | KI10: Ano todo | KJ10: Sim | KK10: Cana-de-açúcar, Silagem de capim, Silagem de milho | KL10: Sim | KN10: Sim | KO10: Sim | KU10: 24 | KV10: 3.25 | KW10: 2.8 | KX10: 3.25 | KY10: Volume de leite entregue, Nível de CCS, Nível de CBT, Teor de gordura, Teor de proteína | KZ10: Sim | LA10: Sim | LB10: Sim | LC10: Sim | LD10: Sim | LG10: Concorda | LH10: Concorda | LI10: Não concorda | LJ10: Sim | LK10: Muito importante
B11: Viçosa | C11: Não familiar | D11: 2) 201 a 500 | E11: Suavemente acidentado ou acidentado | F11: Semiextensivo | G11: Alvenaria | H11: Não possui | I11: Madeira | J11: CAR - Cadastro Ambiental Rural, Cursos d’água/riacho/nascentes/mina, Vegetação nativa/mata/floresta, Área de preservação permanentes, Área de reserva legal, Serviço de telefonia | K11: Sim | L11: Sim | M11: Sim | N11: Sim | O11: Sim | R11: Sim | S11: 36 | T11: 1 | U11: Masculino | V11: Ensino superior completo | W11: Na cidade | X11: 0 | Y11: 100 | Z11: 0 | AA11: 0 | AB11: 0 | AC11: 0 | AD11: 0 | AE11: 0 | AF11: 0 | AG11: 100 | AH11: 0 | AI11: Não | AJ11: 100 | AK11: 0 | AL11: 0 | AM11: 0 | AN11: 0 | AO11: 80 | AP11: 20 | AQ11: 0 | AR11: PRONAMPE | AV11: Sim | BC11: Regular | BD11: Não | BE11: Por ser uma atividade lucrativa, Por proporcionar renda mensal, Tem mercado garantido | BG11: Sim | BH11: Sim | BK11: Sim | BO11: Falta de crédito rural, com taxas de juros compatíveis com a atividade, Instabilidade de políticas públicas | BR11: Sim | BW11: Sim | CB11: Qualidade genética dos animais, Alimentação do rebanho, Conhecimento de técnicas eficientes | CE11: Sim | CF11: Sim | CJ11: Sim | CL11: Aumentar a produção | CM11: Não sabe | CN11: Sim | CO11: PRONAMPE | CR11: Sim | CW11: Utilizou crédito | DC11: Sim | DD11: 500 | DE11: 500 | DF11: 500 | DG11: 16.833333 | DH11: 16 | DI11: 18 | DJ11: 85 | DK11: 0 | DL11: 0 | DM11: 0 | DN11: 15 | DP11: 30 | DQ11: Sim | DR11: Sim | DS11: Não | DT11: 0.92054795 | DU11: 3 | DV11: =DT11+DU11 -> 3.9205479 | DW11: 41 | DX11: 8 | DY11: 1 | DZ11: 6 | EA11: 22 | EB11: 19 | EC11: 17 | ED11: 1 | EE11: 7 | EF11: 0 | EG11: 0 | EH11: 30 | EI11: 0 | EJ11: 70 | EK11: 0 | EL11: 0 | EM11: 0 | EN11: 50 | EO11: 50 | EP11: 0 | EQ11: 0 | ER11: 0 | ES11: 0 | ET11: 0 | EU11: 0 | EV11: Tanque de expansão | EW11: Sim | EX11: Sim | EY11: Sala de ordenha cimentada ou calçada | EZ11: Sim | FA11: Sim | FB11: Mecânica | FC11: 2 | FD11: 2 | FE11: De 2 em 2 dias | FF11: Plantada | FG11: Brachiaria, Panicum, Tifton | FH11: Sim | FI11: Sim | FO11: Sim | FQ11: Correção e adubação do solo na implantação, Adubação anual de cobertura, Controle de plantas invasoras, Rotação de pastagens, Divisão em piquetes, Cerca elétrica nos piquetes | FR11: Sim | FU11: Sim | FV11: Sim | FW11: Sim | FZ11: Apenas o(a) proprietário(a) | GA11: Produção de leite, Produtividade, Receitas, Despesas, Venda de animais | GB11: Sim | GC11: Sim | GD11: Sim | GE11: Sim | GG11: Sim | GI11: Utiliza os indicadores econômicos de forma sistemática para tomada de decisão | GJ11: Sim | GK11: 2.7 | GL11: Assistência técnica | GM11: Sim | GS11: 24 | GT11: Planejamento da empresa rural, Sanidade do rebanho, Manejo do rebanho | GU11: Sim | GY11: Sim | GZ11: Sim | HF11: Melhoramento genético | HM11: Sim | HR11: 0 | HS11: 0 | HT11: 0 | HU11: 100 | HV11: 0 | HW11: Aspersores ou nebulizadores | IH11: Residência e locais de produção | II11: Em toda fazenda | IJ11: Picadeira, Misturador de ração | IK11: Sim | IT11: Sim | IU11: Não tem destino certo | IV11: Plantio direto, Descarte adequado de embalagens (herbicida e defensivos) | IW11: Sim | IY11: Sim | JB11: 10 | JC11: 2.5 | JD11: 100 | JE11: 29 | JF11: 13 | JG11: 8 | JH11: 0 | JI11: Manqueira, Brucelose, Raiva, Enterotoxemia, Botulismo, Vermifugação, Carrapaticida, IBR/BVD, Leptospirose | JJ11: Sim | JK11: Sim | JM11: Sim | JN11: Sim | JO11: Sim | JP11: Sim | JQ11: Sim | JR11: Sim | JS11: Sim | JT11: Teste da caneca, Pré-dipping, Pós-dipping, Alimentação durante a ordenha, Alimentação após a ordenha | JU11: Sim | JV11: Sim | JW11: Sim | JY11: Sim | JZ11: Sim | KB11: FIV/TE, Inseminação artificial/IATF | KC11: Sim | KD11: Sim | KG11: Artificial | KH11: Peso das novilhas | KI11: Ano todo | KJ11: Sim | KK11: Cana-de-açúcar, Silagem de milho | KL11: Sim | KO11: Sim | KU11: 1 | KV11: 2.93 | KW11: 2.3 | KX11: 2.8 | KY11: Volume de leite entregue, Nível de CCS, Nível de CBT, Teor de gordura, Teor de proteína | KZ11: Sim | LA11: Sim | LB11: Sim | LC11: Sim | LD11: Sim | LG11: Não concorda | LH11: Concorda | LI11: Concorda | LJ11: Não | LK11: Muito importante
